{"uuid": "d71dad69-710c-40c5-a556-e2f87a69b15d", "children": ["0c96e3c2-dc69-4f7f-bf47-ea974b5a4786"], "befores": [{"name": "driver", "status": "broken", "statusDetails": {"message": "urllib3.exceptions.ProtocolError: ('Connection aborted.', ConnectionResetError(10054, 'Удаленный хост принудительно разорвал существующее подключение', None, 10054, None))\n", "trace": "  File \"D:\\Anaconda3\\envs\\final_project\\lib\\site-packages\\pluggy\\_callers.py\", line 39, in _multicall\n    res = hook_impl.function(*args)\n  File \"D:\\Anaconda3\\envs\\final_project\\lib\\site-packages\\_pytest\\fixtures.py\", line 1126, in pytest_fixture_setup\n    result = call_fixture_func(fixturefunc, request, kwargs)\n  File \"D:\\Anaconda3\\envs\\final_project\\lib\\site-packages\\_pytest\\fixtures.py\", line 925, in call_fixture_func\n    fixture_result = next(generator)\n  File \"D:\\ProgrammingProjects\\PythonProj\\final_project\\vkidTest\\src\\ui\\fixtures.py\", line 72, in driver\n    browser = get_driver(config, download_dir=temp_dir)\n  File \"D:\\ProgrammingProjects\\PythonProj\\final_project\\vkidTest\\src\\ui\\fixtures.py\", line 53, in get_driver\n    browser = webdriver.Remote(selenoid, desired_capabilities=capabilities)\n  File \"D:\\Anaconda3\\envs\\final_project\\lib\\site-packages\\selenium\\webdriver\\remote\\webdriver.py\", line 268, in __init__\n    self.start_session(capabilities, browser_profile)\n  File \"D:\\Anaconda3\\envs\\final_project\\lib\\site-packages\\selenium\\webdriver\\remote\\webdriver.py\", line 359, in start_session\n    response = self.execute(Command.NEW_SESSION, parameters)\n  File \"D:\\Anaconda3\\envs\\final_project\\lib\\site-packages\\selenium\\webdriver\\remote\\webdriver.py\", line 422, in execute\n    response = self.command_executor.execute(driver_command, params)\n  File \"D:\\Anaconda3\\envs\\final_project\\lib\\site-packages\\selenium\\webdriver\\remote\\remote_connection.py\", line 421, in execute\n    return self._request(command_info[0], url, body=data)\n  File \"D:\\Anaconda3\\envs\\final_project\\lib\\site-packages\\selenium\\webdriver\\remote\\remote_connection.py\", line 443, in _request\n    resp = self._conn.request(method, url, body=body, headers=headers)\n  File \"D:\\Anaconda3\\envs\\final_project\\lib\\site-packages\\urllib3\\request.py\", line 78, in request\n    return self.request_encode_body(\n  File \"D:\\Anaconda3\\envs\\final_project\\lib\\site-packages\\urllib3\\request.py\", line 170, in request_encode_body\n    return self.urlopen(method, url, **extra_kw)\n  File \"D:\\Anaconda3\\envs\\final_project\\lib\\site-packages\\urllib3\\poolmanager.py\", line 375, in urlopen\n    response = conn.urlopen(method, u.request_uri, **kw)\n  File \"D:\\Anaconda3\\envs\\final_project\\lib\\site-packages\\urllib3\\connectionpool.py\", line 755, in urlopen\n    retries = retries.increment(\n  File \"D:\\Anaconda3\\envs\\final_project\\lib\\site-packages\\urllib3\\util\\retry.py\", line 532, in increment\n    raise six.reraise(type(error), error, _stacktrace)\n  File \"D:\\Anaconda3\\envs\\final_project\\lib\\site-packages\\urllib3\\packages\\six.py\", line 769, in reraise\n    raise value.with_traceback(tb)\n  File \"D:\\Anaconda3\\envs\\final_project\\lib\\site-packages\\urllib3\\connectionpool.py\", line 699, in urlopen\n    httplib_response = self._make_request(\n  File \"D:\\Anaconda3\\envs\\final_project\\lib\\site-packages\\urllib3\\connectionpool.py\", line 445, in _make_request\n    six.raise_from(e, None)\n  File \"<string>\", line 3, in raise_from\n  File \"D:\\Anaconda3\\envs\\final_project\\lib\\site-packages\\urllib3\\connectionpool.py\", line 440, in _make_request\n    httplib_response = conn.getresponse()\n  File \"D:\\Anaconda3\\envs\\final_project\\lib\\http\\client.py\", line 1371, in getresponse\n    response.begin()\n  File \"D:\\Anaconda3\\envs\\final_project\\lib\\http\\client.py\", line 319, in begin\n    version, status, reason = self._read_status()\n  File \"D:\\Anaconda3\\envs\\final_project\\lib\\http\\client.py\", line 280, in _read_status\n    line = str(self.fp.readline(_MAXLINE + 1), \"iso-8859-1\")\n  File \"D:\\Anaconda3\\envs\\final_project\\lib\\socket.py\", line 704, in readinto\n    return self._sock.recv_into(b)\n"}, "steps": [{"name": "Init browser", "status": "broken", "statusDetails": {"message": "urllib3.exceptions.ProtocolError: ('Connection aborted.', ConnectionResetError(10054, 'Удаленный хост принудительно разорвал существующее подключение', None, 10054, None))\n", "trace": "  File \"D:\\ProgrammingProjects\\PythonProj\\final_project\\vkidTest\\src\\ui\\fixtures.py\", line 72, in driver\n    browser = get_driver(config, download_dir=temp_dir)\n  File \"D:\\ProgrammingProjects\\PythonProj\\final_project\\vkidTest\\src\\ui\\fixtures.py\", line 53, in get_driver\n    browser = webdriver.Remote(selenoid, desired_capabilities=capabilities)\n  File \"D:\\Anaconda3\\envs\\final_project\\lib\\site-packages\\selenium\\webdriver\\remote\\webdriver.py\", line 268, in __init__\n    self.start_session(capabilities, browser_profile)\n  File \"D:\\Anaconda3\\envs\\final_project\\lib\\site-packages\\selenium\\webdriver\\remote\\webdriver.py\", line 359, in start_session\n    response = self.execute(Command.NEW_SESSION, parameters)\n  File \"D:\\Anaconda3\\envs\\final_project\\lib\\site-packages\\selenium\\webdriver\\remote\\webdriver.py\", line 422, in execute\n    response = self.command_executor.execute(driver_command, params)\n  File \"D:\\Anaconda3\\envs\\final_project\\lib\\site-packages\\selenium\\webdriver\\remote\\remote_connection.py\", line 421, in execute\n    return self._request(command_info[0], url, body=data)\n  File \"D:\\Anaconda3\\envs\\final_project\\lib\\site-packages\\selenium\\webdriver\\remote\\remote_connection.py\", line 443, in _request\n    resp = self._conn.request(method, url, body=body, headers=headers)\n  File \"D:\\Anaconda3\\envs\\final_project\\lib\\site-packages\\urllib3\\request.py\", line 78, in request\n    return self.request_encode_body(\n  File \"D:\\Anaconda3\\envs\\final_project\\lib\\site-packages\\urllib3\\request.py\", line 170, in request_encode_body\n    return self.urlopen(method, url, **extra_kw)\n  File \"D:\\Anaconda3\\envs\\final_project\\lib\\site-packages\\urllib3\\poolmanager.py\", line 375, in urlopen\n    response = conn.urlopen(method, u.request_uri, **kw)\n  File \"D:\\Anaconda3\\envs\\final_project\\lib\\site-packages\\urllib3\\connectionpool.py\", line 755, in urlopen\n    retries = retries.increment(\n  File \"D:\\Anaconda3\\envs\\final_project\\lib\\site-packages\\urllib3\\util\\retry.py\", line 532, in increment\n    raise six.reraise(type(error), error, _stacktrace)\n  File \"D:\\Anaconda3\\envs\\final_project\\lib\\site-packages\\urllib3\\packages\\six.py\", line 769, in reraise\n    raise value.with_traceback(tb)\n  File \"D:\\Anaconda3\\envs\\final_project\\lib\\site-packages\\urllib3\\connectionpool.py\", line 699, in urlopen\n    httplib_response = self._make_request(\n  File \"D:\\Anaconda3\\envs\\final_project\\lib\\site-packages\\urllib3\\connectionpool.py\", line 445, in _make_request\n    six.raise_from(e, None)\n  File \"<string>\", line 3, in raise_from\n  File \"D:\\Anaconda3\\envs\\final_project\\lib\\site-packages\\urllib3\\connectionpool.py\", line 440, in _make_request\n    httplib_response = conn.getresponse()\n  File \"D:\\Anaconda3\\envs\\final_project\\lib\\http\\client.py\", line 1371, in getresponse\n    response.begin()\n  File \"D:\\Anaconda3\\envs\\final_project\\lib\\http\\client.py\", line 319, in begin\n    version, status, reason = self._read_status()\n  File \"D:\\Anaconda3\\envs\\final_project\\lib\\http\\client.py\", line 280, in _read_status\n    line = str(self.fp.readline(_MAXLINE + 1), \"iso-8859-1\")\n  File \"D:\\Anaconda3\\envs\\final_project\\lib\\socket.py\", line 704, in readinto\n    return self._sock.recv_into(b)\n"}, "start": 1640022687168, "stop": 1640022698192}], "start": 1640022687153, "stop": 1640022701652}], "start": 1640022687153, "stop": 1640022712161}